#VRML_SIM R2022b utf8

EXTERNPROTO "https://raw.githubusercontent.com/cyberbotics/webots/R2022b/projects/objects/backgrounds/protos/TexturedBackground.proto"
EXTERNPROTO "https://raw.githubusercontent.com/cyberbotics/webots/R2022b/projects/objects/backgrounds/protos/TexturedBackgroundLight.proto"
EXTERNPROTO "https://raw.githubusercontent.com/cyberbotics/webots/R2022b/projects/objects/floors/protos/RectangleArena.proto"
EXTERNPROTO "https://raw.githubusercontent.com/cyberbotics/webots/R2022b/projects/objects/factory/containers/protos/WoodenBox.proto"
EXTERNPROTO "https://raw.githubusercontent.com/cyberbotics/webots/R2022b/projects/robots/gctronic/e-puck/protos/E-puck.proto"

WorldInfo {
  basicTimeStep 16
  FPS 30
  physicsDisableTime 0
  defaultDamping Damping {
  }
  contactProperties [
    ContactProperties {
      material2 "dumbbell"
      coulombFriction [
        0
      ]
    }
  ]
}
Viewpoint {
  orientation -0.4280584050949872 0.09377399953473296 0.8988728713443275 2.434349950937008
  position 0.7015530639698155 -0.7040428698287767 1.0732725993499803
}
TexturedBackground {
}
TexturedBackgroundLight {
}
RectangleArena {
  rotation 0 1 0 0
  floorTileSize 0.25 0.25
  wallHeight 0.05
}
WoodenBox {
  translation 0.197269 -0.622728 0.5
  rotation 0 0 1 0.785398
  size 0.1 0.1 0.1
}
E-puck {
  translation -0.241839 0.119481 -4.44089e-15
  rotation 0 0 1 -1.047195307179586
  controller "epuck_go_forward"
}
WoodenBox {
  translation 0.273549 -0.0522784 0.02
  name "wooden box(2)"
  size 0.1 0.1 0.1
  mass 0.2
}
WoodenBox {
  translation -0.485507 0.0404783 0.5
  name "wooden box(1)"
  size 0.1 0.1 0.1
}
Robot {
  translation 0 0 0.04
  children [
    DEF DS_RIGHT DistanceSensor {
      translation 0.1 -0.03 0
      rotation 0 0 1 -0.261799
      children [
        DEF SENSORE Shape {
          appearance PBRAppearance {
            baseColor 0 0 1
            metalness 0
          }
          geometry Box {
            size 0.01 0.01 0.01
          }
        }
      ]
      name "ds_right"
      boundingObject USE SENSORE
      physics DEF SENSOR Physics {
      }
    }
    DEF DS_LEFT DistanceSensor {
      translation 0.1 0.03 0
      rotation 0 0 1 0.261799
      children [
        USE SENSORE
      ]
      name "ds_left"
      boundingObject USE SENSORE
      physics USE SENSOR
    }
    DEF CUERPO Shape {
      appearance PBRAppearance {
        baseColor 1 0 0
        metalness 0
      }
      geometry Box {
        size 0.2 0.1 0.05
      }
    }
    DEF WHEEL1 HingeJoint {
      jointParameters HingeJointParameters {
        axis 0 1 0
        anchor 0.05 0.06 0
      }
      device [
        RotationalMotor {
          name "wheel1"
        }
      ]
      endPoint DEF WHEEL1 Solid {
        translation 0.05 0.06 0
        rotation 1 0 0 1.5708
        children [
          DEF WHEEL Shape {
            appearance PBRAppearance {
              baseColor 0 1 0
              metalness 0
            }
            geometry Cylinder {
              height 0.02
              radius 0.04
            }
          }
        ]
        name "solid(3)"
        boundingObject USE WHEEL
        physics DEF WHEEL_PH Physics {
        }
      }
    }
    DEF WHEEL2 HingeJoint {
      jointParameters HingeJointParameters {
        axis 0 1 0
        anchor 0.05 -0.06 0
      }
      device [
        RotationalMotor {
          name "wheel2"
        }
      ]
      endPoint DEF WHEEL1 Solid {
        translation 0.05 -0.06 0
        rotation 1 -1.5700895750559031e-16 0 1.5707999999999998
        children [
          USE WHEEL
        ]
        name "solid(2)"
        boundingObject USE WHEEL
        physics USE WHEEL_PH
      }
    }
    DEF WHEEL3 HingeJoint {
      jointParameters HingeJointParameters {
        axis 0 1 0
        anchor -0.05 0.06 0
      }
      device [
        RotationalMotor {
          name "wheel3"
        }
      ]
      endPoint DEF WHEEL1 Solid {
        translation -0.05 0.06 0
        rotation 1 0 0 1.5708000000000004
        children [
          USE WHEEL
        ]
        name "solid(1)"
        boundingObject USE WHEEL
        physics USE WHEEL_PH
      }
    }
    DEF WHEEL4 HingeJoint {
      jointParameters HingeJointParameters {
        axis 0 1 0
        anchor -0.05 -0.06 0
      }
      device [
        RotationalMotor {
          name "wheel4"
        }
      ]
      endPoint DEF WHEEL1 Solid {
        translation -0.05 -0.06 0
        rotation 1 -7.850447875279518e-17 3.925223937639759e-17 1.5707999999999995
        children [
          USE WHEEL
        ]
        boundingObject USE WHEEL
        physics USE WHEEL_PH
      }
    }
  ]
  boundingObject USE CUERPO
  physics Physics {
  }
  controller "controladorRObot4rueda"
}
